Failure # 1 (occurred at 2025-04-25_11-35-32)
[36mray::ImplicitFunc.train()[39m (pid=22752, ip=127.0.0.1, actor_id=badff9acc538e984be0d5f5201000000, repr=train_rl_agent_tune)
  File "python\ray\_raylet.pyx", line 1883, in ray._raylet.execute_task
  File "python\ray\_raylet.pyx", line 1824, in ray._raylet.execute_task.function_executor
  File "C:\Users\user\AppData\Local\Programs\Python\Python310\lib\site-packages\ray\_private\function_manager.py", line 696, in actor_method_executor
    return method(__ray_actor, *args, **kwargs)
  File "C:\Users\user\AppData\Local\Programs\Python\Python310\lib\site-packages\ray\util\tracing\tracing_helper.py", line 463, in _resume_span
    return method(self, *_args, **_kwargs)
  File "C:\Users\user\AppData\Local\Programs\Python\Python310\lib\site-packages\ray\tune\trainable\trainable.py", line 331, in train
    raise skipped from exception_cause(skipped)
  File "C:\Users\user\AppData\Local\Programs\Python\Python310\lib\site-packages\ray\air\_internal\util.py", line 107, in run
    self._ret = self._target(*self._args, **self._kwargs)
  File "C:\Users\user\AppData\Local\Programs\Python\Python310\lib\site-packages\ray\tune\trainable\function_trainable.py", line 45, in <lambda>
    training_func=lambda: self._trainable_func(self.config),
  File "C:\Users\user\AppData\Local\Programs\Python\Python310\lib\site-packages\ray\util\tracing\tracing_helper.py", line 463, in _resume_span
    return method(self, *_args, **_kwargs)
  File "C:\Users\user\AppData\Local\Programs\Python\Python310\lib\site-packages\ray\tune\trainable\function_trainable.py", line 261, in _trainable_func
    output = fn()
  File "C:\Users\user\Desktop\ltsm-dqn\rl_agent\train.py", line 536, in train_rl_agent_tune
    model.learn(
  File "C:\Users\user\AppData\Local\Programs\Python\Python310\lib\site-packages\stable_baselines3\ppo\ppo.py", line 311, in learn
    return super().learn(
  File "C:\Users\user\AppData\Local\Programs\Python\Python310\lib\site-packages\stable_baselines3\common\on_policy_algorithm.py", line 324, in learn
    continue_training = self.collect_rollouts(self.env, callback, self.rollout_buffer, n_rollout_steps=self.n_steps)
  File "C:\Users\user\AppData\Local\Programs\Python\Python310\lib\site-packages\stable_baselines3\common\on_policy_algorithm.py", line 218, in collect_rollouts
    new_obs, rewards, dones, infos = env.step(clipped_actions)
  File "C:\Users\user\AppData\Local\Programs\Python\Python310\lib\site-packages\stable_baselines3\common\vec_env\base_vec_env.py", line 222, in step
    return self.step_wait()
  File "C:\Users\user\AppData\Local\Programs\Python\Python310\lib\site-packages\stable_baselines3\common\vec_env\vec_normalize.py", line 181, in step_wait
    obs, rewards, dones, infos = self.venv.step_wait()
  File "C:\Users\user\AppData\Local\Programs\Python\Python310\lib\site-packages\stable_baselines3\common\vec_env\dummy_vec_env.py", line 59, in step_wait
    obs, self.buf_rews[env_idx], terminated, truncated, self.buf_infos[env_idx] = self.envs[env_idx].step(  # type: ignore[assignment]
  File "C:\Users\user\AppData\Local\Programs\Python\Python310\lib\site-packages\stable_baselines3\common\monitor.py", line 94, in step
    observation, reward, terminated, truncated, info = self.env.step(action)
  File "C:\Users\user\AppData\Local\Programs\Python\Python310\lib\site-packages\stable_baselines3\common\monitor.py", line 94, in step
    observation, reward, terminated, truncated, info = self.env.step(action)
  File "C:\Users\user\Desktop\ltsm-dqn\rl_agent\environment\trading_env.py", line 404, in step
    info = self._get_info() # Based on self.current_step (t+1)
  File "C:\Users\user\Desktop\ltsm-dqn\rl_agent\environment\trading_env.py", line 958, in _get_info
    portfolio_returns = np.diff(pv_array[valid_indices + 1]) / pv_array[valid_indices] # noqa E501
ValueError: operands could not be broadcast together with shapes (2,) (3,)
