Failure # 1 (occurred at 2025-04-25_11-10-26)
[36mray::ImplicitFunc.train()[39m (pid=22568, ip=127.0.0.1, actor_id=ae0289c9d7342868af2033ee01000000, repr=train_rl_agent_tune)
  File "python\ray\_raylet.pyx", line 1883, in ray._raylet.execute_task
  File "python\ray\_raylet.pyx", line 1824, in ray._raylet.execute_task.function_executor
  File "C:\Users\user\AppData\Local\Programs\Python\Python310\lib\site-packages\ray\_private\function_manager.py", line 696, in actor_method_executor
    return method(__ray_actor, *args, **kwargs)
  File "C:\Users\user\AppData\Local\Programs\Python\Python310\lib\site-packages\ray\util\tracing\tracing_helper.py", line 463, in _resume_span
    return method(self, *_args, **_kwargs)
  File "C:\Users\user\AppData\Local\Programs\Python\Python310\lib\site-packages\ray\tune\trainable\trainable.py", line 331, in train
    raise skipped from exception_cause(skipped)
  File "C:\Users\user\AppData\Local\Programs\Python\Python310\lib\site-packages\ray\air\_internal\util.py", line 107, in run
    self._ret = self._target(*self._args, **self._kwargs)
  File "C:\Users\user\AppData\Local\Programs\Python\Python310\lib\site-packages\ray\tune\trainable\function_trainable.py", line 45, in <lambda>
    training_func=lambda: self._trainable_func(self.config),
  File "C:\Users\user\AppData\Local\Programs\Python\Python310\lib\site-packages\ray\util\tracing\tracing_helper.py", line 463, in _resume_span
    return method(self, *_args, **_kwargs)
  File "C:\Users\user\AppData\Local\Programs\Python\Python310\lib\site-packages\ray\tune\trainable\function_trainable.py", line 261, in _trainable_func
    output = fn()
  File "C:\Users\user\Desktop\ltsm-dqn\rl_agent\train.py", line 372, in train_rl_agent_tune
    tune.report(**initial_metrics)
  File "C:\Users\user\AppData\Local\Programs\Python\Python310\lib\site-packages\ray\train\_internal\session.py", line 663, in wrapper
    return fn(*args, **kwargs)
TypeError: report() got an unexpected keyword argument 'training_iteration'
