Failure # 1 (occurred at 2025-04-26_21-45-34)
[36mray::ImplicitFunc.train()[39m (pid=24528, ip=127.0.0.1, actor_id=922c9cd2339d26ca34ec1d2001000000, repr=train_rl_agent_tune)
  File "python\ray\_raylet.pyx", line 1883, in ray._raylet.execute_task
  File "python\ray\_raylet.pyx", line 1824, in ray._raylet.execute_task.function_executor
  File "C:\Users\user\AppData\Local\Programs\Python\Python310\lib\site-packages\ray\_private\function_manager.py", line 696, in actor_method_executor
    return method(__ray_actor, *args, **kwargs)
  File "C:\Users\user\AppData\Local\Programs\Python\Python310\lib\site-packages\ray\util\tracing\tracing_helper.py", line 463, in _resume_span
    return method(self, *_args, **_kwargs)
  File "C:\Users\user\AppData\Local\Programs\Python\Python310\lib\site-packages\ray\tune\trainable\trainable.py", line 331, in train
    raise skipped from exception_cause(skipped)
  File "C:\Users\user\AppData\Local\Programs\Python\Python310\lib\site-packages\ray\air\_internal\util.py", line 107, in run
    self._ret = self._target(*self._args, **self._kwargs)
  File "C:\Users\user\AppData\Local\Programs\Python\Python310\lib\site-packages\ray\tune\trainable\function_trainable.py", line 45, in <lambda>
    training_func=lambda: self._trainable_func(self.config),
  File "C:\Users\user\AppData\Local\Programs\Python\Python310\lib\site-packages\ray\util\tracing\tracing_helper.py", line 463, in _resume_span
    return method(self, *_args, **_kwargs)
  File "C:\Users\user\AppData\Local\Programs\Python\Python310\lib\site-packages\ray\tune\trainable\function_trainable.py", line 261, in _trainable_func
    output = fn()
  File "C:\Users\user\Desktop\ltsm-dqn\rl_agent\train.py", line 732, in train_rl_agent_tune
    train_env = make_vec_env(
  File "C:\Users\user\Desktop\ltsm-dqn\rl_agent\train.py", line 151, in make_vec_env
    return vec_env_cls([make_env(i) for i in range(n_envs)])
  File "C:\Users\user\AppData\Local\Programs\Python\Python310\lib\site-packages\stable_baselines3\common\vec_env\dummy_vec_env.py", line 31, in __init__
    self.envs = [_patch_env(fn()) for fn in env_fns]
  File "C:\Users\user\AppData\Local\Programs\Python\Python310\lib\site-packages\stable_baselines3\common\vec_env\dummy_vec_env.py", line 31, in <listcomp>
    self.envs = [_patch_env(fn()) for fn in env_fns]
  File "C:\Users\user\Desktop\ltsm-dqn\rl_agent\train.py", line 140, in _init
    env = env_id()
  File "C:\Users\user\Desktop\ltsm-dqn\rl_agent\train.py", line 717, in _init
    env = create_env(config=env_config, is_eval=False)
  File "C:\Users\user\Desktop\ltsm-dqn\rl_agent\train.py", line 1333, in create_env
    data_15m = DataLoader(data_path=data_path, data_key="/15m").load_data()
  File "C:\Users\user\Desktop\ltsm-dqn\rl_agent\data\data_loader.py", line 88, in __init__
    raise FileNotFoundError(f"Data file not found: {self.data_path}")
FileNotFoundError: Data file not found: C:\Users\user\Desktop\ltsm-dqn\data\historic_nom\train_fp16.h5
